<sdf version='1.6'>
  <world name='default'>
    <light name="sun" type="directional">
     <pose frame="">0 0 2 0 0 0</pose>
      <diffuse>0.8 0.8 0.8 1</diffuse>
      <specular>.1 .1 .1 1</specular>
      <attenuation>
      <range>1000</range>
        <linear>0.2</linear>
        <constant>0.8</constant>
        <quadratic>0.001</quadratic>
      </attenuation>
      <cast_shadows>true</cast_shadows>
      <direction>-0.5 0.5 -1</direction>
    </light>
    <gravity>0 0 -9.8</gravity>
    <magnetic_field>6e-06 2.3e-05 -4.2e-05</magnetic_field>
    <atmosphere type='adiabatic'/>
    <physics name='default_physics' default='0' type='ode'>
      <max_step_size>0.001</max_step_size>
      <real_time_factor>1</real_time_factor>
      <real_time_update_rate>1000</real_time_update_rate>
    </physics>
    <scene>
      <ambient>0.4 0.4 0.4 1</ambient>
      <background>0.7 0.7 0.7 1</background>
      <shadows>1</shadows>
    </scene>
    <spherical_coordinates>
      <surface_model>EARTH_WGS84</surface_model>
      <latitude_deg>0</latitude_deg>
      <longitude_deg>0</longitude_deg>
      <elevation>0</elevation>
      <heading_deg>0</heading_deg>
    </spherical_coordinates>
    <model name='ground_plane'>
      <static>1</static>
      <link name='link'>
        <collision name='collision'>
          <geometry>
            <plane>
              <normal>0 0 1</normal>
              <size>100 100</size>
            </plane>
          </geometry>
          <surface>
            <friction>
              <ode>
                <mu>100</mu>
                <mu2>50</mu2>
              </ode>
              <torsional>
                <ode/>
              </torsional>
            </friction>
            <contact>
              <ode/>
            </contact>
            <bounce/>
          </surface>
          <max_contacts>10</max_contacts>
        </collision>
        <visual name='visual'>
          <cast_shadows>0</cast_shadows>
          <geometry>
            <plane>
              <normal>0 0 1</normal>
              <size>100 100</size>
            </plane>
          </geometry>
          <material>
            <script>
              <uri>file://media/materials/scripts/gazebo.material</uri>
              <name>Gazebo/Grey</name>
            </script>
          </material>
        </visual>
        <self_collide>0</self_collide>
        <kinematic>0</kinematic>
        <gravity>1</gravity>
      </link>
      <pose frame=''>2.62989 -2.33764 0 0 -0 0</pose>
    </model>
    <state world_name='default'>
      <sim_time>0 0</sim_time>
      <real_time>0 0</real_time>
      <wall_time>1541980466 706198982</wall_time>
      <iterations>0</iterations>
      <model name='ground_plane'>
        <pose frame=''>0 0 0 0 -0 0</pose>
        <scale>1 1 1</scale>
        <link name='link'>
          <pose frame=''>0 0 0 0 -0 0</pose>
          <velocity>0 0 0 0 -0 0</velocity>
          <acceleration>0 0 0 0 -0 0</acceleration>
          <wrench>0 0 0 0 -0 0</wrench>
        </link>
      </model>
    </state>
    <gui fullscreen='0'>
      <camera name='user_camera'>
        <pose frame=''>5.32218 -4.84676 1.57764 0 0.275643 2.35619</pose>
        <view_controller>orbit</view_controller>
        <projection_type>perspective</projection_type>
      </camera> 
    </gui>
    
    <model name="mirobot">
     <pose frame="">0 0 0 0 0 0</pose>
     <self_collide>true</self_collide>
     
     <link name="base">
     <pose>0 0 0.10 0 0 0</pose>
     <collision name="baseC">
         <pose>0 0 0 0 0 0</pose>
         <inertia>
         <mass>20</mass>
         </inertia>
         <geometry>
         <box>
         <size>0.5 1 0.2</size>
        </box>
         </geometry>
    <surface>
     <contact>
     <ode>
     <soft_cfm>0</soft_cfm>
     <soft_erp>0.2</soft_erp>
     <kp>1e+13</kp>
     <kd>1e+11</kd>
     <max_vel>-1</max_vel>
     <min_depth>0</min_depth>
     </ode>
    </contact>
    </surface>
  </collision>
     <visual name="baseV">
      <pose>0 0 0 0 0 0</pose>
      <geometry>
       <box>
         <size>0.5 1 0.2</size>
        </box>
    </geometry>
    </visual>
    </link>
    
    
     <link name="eslabon1">
     <pose>0 0 0.7 0 0 0</pose>
     <collision name="eslabon1C">
      <pose>0 0 0 0 0 0</pose>
      <geometry>
       <box>
         <size>0.05 0.05 1</size>
        </box>
    </geometry>
    <surface>
     <contact>
     <ode>
     <soft_cfm>0</soft_cfm>
     <soft_erp>0.2</soft_erp>
     <kp>1e+13</kp>
     <kd>1e+11</kd>
     <max_vel>-1</max_vel>
     <min_depth>0</min_depth>
     </ode>
    </contact>
    </surface>
    </collision>
     <visual name="eslabon1C">
      <pose>0 0 0 0 0 0</pose>
      <geometry>
       <box>
         <size>0.05 0.05 1</size>
        </box>
    </geometry>
    </visual>
    </link>
    
    <joint name="eslabon1J" type="revolute">
    <pose frame="">0 0 -0.5 0 0 0</pose>
    <parent>base</parent>
    <child>eslabon1</child>
    <axis>
      <dynamics>
      <damping>1</damping>
      <friction>0</friction>
      <spring_reference>0</spring_reference>
      <spring_stiffness>0</spring_stiffness>
      </dynamics> 
      <limit>
      <lower>-3.14</lower>
      <upper>3.14</upper>
      <!--effort>0</effort>
      <velocity>0</velocity-->
      </limit>
      <xyz>0 0 1</xyz>
      <use_parent_model_frame>1</use_parent_model_frame>
    </axis>
    </joint>
    
    <link name="eslabon2">
     <pose>0.0 -0.05 1.65 0 0 0</pose>
     <collision name="eslabon2">
      <pose>0 0 0 0 0 0</pose>
      <geometry>
       <box>
         <size>0.05 0.05 1</size>
        </box>
    </geometry>
    <surface>
     <contact>
     <ode>
     <soft_cfm>0</soft_cfm>
     <soft_erp>0.2</soft_erp>
     <kp>1e+13</kp>
     <kd>1e+11</kd>
     <max_vel>-1</max_vel>
     <min_depth>0</min_depth>
     </ode>
    </contact>
    </surface>
    </collision>
     <visual name="eslabon2">
      <pose>0 0 0 0 0 0</pose>
      <geometry>
       <box>
         <size>0.05 0.05 1</size>
        </box>
    </geometry>
    </visual>
    </link>
    
    <joint name="eslabon2J" type="revolute">
    <pose frame="">0 0 -0.475 0 0 0</pose>
    <parent>eslabon1</parent>
    <child>eslabon2</child>
    <axis>
      <dynamics>
      <damping>1</damping>
      <friction>0</friction>
      <spring_reference>0</spring_reference>
      <spring_stiffness>0</spring_stiffness>
      </dynamics> 
      <limit>
      <lower>-3.14</lower>
      <upper>3.14</upper>
      <!--effort>0</effort>
      <velocity>0</velocity-->
      </limit>
      <xyz>0 1 0</xyz>
      <use_parent_model_frame>1</use_parent_model_frame>
    </axis>
    </joint>
    
    
    <link name="eslabon3">
     <pose>0.0 0.0 2.60 0 0 0</pose>
     <collision name="eslabon3">
      <pose>0 0 0 0 0 0</pose>
      <geometry>
       <box>
         <size>0.05 0.05 1</size>
        </box>
    </geometry>
    <surface>
     <contact>
     <ode>
     <soft_cfm>0</soft_cfm>
     <soft_erp>0.2</soft_erp>
     <kp>1e+13</kp>
     <kd>1e+11</kd>
     <max_vel>-1</max_vel>
     <min_depth>0</min_depth>
     </ode>
    </contact>
    </surface>
    </collision>
     <visual name="eslabon3">
      <pose>0 0 0 0 0 0</pose>
      <geometry>
       <box>
         <size>0.05 0.05 1</size>
        </box>
    </geometry>
    </visual>
    </link>
    
    
    <joint name="eslabon3J" type="revolute">
    <pose frame="">0 0 -0.475 0 0 0</pose>
    <parent>eslabon2</parent>
    <child>eslabon3</child>
    <axis>
      <dynamics>
      <damping>1</damping>
      <friction>0</friction>
      <spring_reference>0</spring_reference>
      <spring_stiffness>0</spring_stiffness>
      </dynamics> 
      <limit>
      <lower>-3.14</lower>
      <upper>3.14</upper>
      <!--effort>0</effort>
      <velocity>0</velocity-->
      </limit>
      <xyz>0 1 0</xyz>
      <use_parent_model_frame>1</use_parent_model_frame>
    </axis>
    </joint>
    
    
    
    <link name="mano">
     <pose>0.0 0.0 3.10 0 0 0</pose>
     <collision name="mano">
      <pose>0 0 0 0 0 0</pose>
      <geometry>
       <box>
         <size>0.10 0.10 0.10</size>
        </box>
    </geometry>
    <surface>
     <contact>
     <ode>
     <soft_cfm>0</soft_cfm>
     <soft_erp>0.2</soft_erp>
     <kp>1e+13</kp>
     <kd>1e+11</kd>
     <max_vel>-1</max_vel>
     <min_depth>0</min_depth>
     </ode>
    </contact>
    </surface>
    </collision>
     <visual name="mano">
      <pose>0 0 0 0 0 0</pose>
      <geometry>
       <box>
         <size>0.1 0.1 0.1</size>
        </box>
    </geometry>
    </visual>
    </link>
    
    
     <joint name="muneca" type="revolute">
    <pose frame="">0 0 -0.475 0 0 0</pose>
    <parent>eslabon3</parent>
    <child>mano</child>
    <axis>
      <dynamics>
      <damping>1</damping>
      <friction>0</friction>
      <spring_reference>0</spring_reference>
      <spring_stiffness>0</spring_stiffness>
      </dynamics> 
      <limit>
      <lower>-3.14</lower>
      <upper>3.14</upper>
      <!--effort>0</effort>
      <velocity>0</velocity-->
      </limit>
      <xyz>0 0 1</xyz>
      <use_parent_model_frame>1</use_parent_model_frame>
    </axis>
    </joint>
    
    <link name="dedo1">
     <pose>0.01 0.04 3.175 0 0 0</pose>
     <collision name="dedo1">
      <pose>0 0 0 0 0 0</pose>
      <geometry>
       <box>
         <size>0.10 0.10 0.10</size>
        </box>
    </geometry>
    <surface>
     <contact>
     <ode>
     <soft_cfm>0</soft_cfm>
     <soft_erp>0.2</soft_erp>
     <kp>1e+13</kp>
     <kd>1e+11</kd>
     <max_vel>-1</max_vel>
     <min_depth>0</min_depth>
     </ode>
    </contact>
    </surface>
    </collision>
     <visual name="dedo1">
      <pose>0 0 0 0 0 0</pose>
      <geometry>
       <box>
         <size>0.02 0.02 0.05</size>
        </box>
    </geometry>
    </visual>
    </link>
    
    
    <link name="dedo2">
     <pose>0.01 -0.04 3.175 0 0 0</pose>
     <collision name="dedo2">
      <pose>0 0 0 0 0 0</pose>
      <geometry>
       <box>
         <size>0.10 0.10 0.10</size>
        </box>
    </geometry>
    <surface>
     <contact>
     <ode>
     <soft_cfm>0</soft_cfm>
     <soft_erp>0.2</soft_erp>
     <kp>1e+13</kp>
     <kd>1e+11</kd>
     <max_vel>-1</max_vel>
     <min_depth>0</min_depth>
     </ode>
    </contact>
    </surface>
    </collision>
     <visual name="dedo2">
      <pose>0 0 0 0 0 0</pose>
      <geometry>
       <box>
         <size>0.02 0.02 0.05</size>
        </box>
    </geometry>
    </visual>
    </link>
    
    <joint name="dedo1J" type="prismatic">
    <pose frame="">0 0 0.1 0 0 0</pose>
    <parent>mano</parent>
    <child>dedo1</child>
    <axis>
      <dynamics>
      <damping>1</damping>
      <friction>0</friction>
      <spring_reference>0</spring_reference>
      <spring_stiffness>0</spring_stiffness>
      </dynamics> 
      <limit>
      <lower>-0</lower>
      <upper>0.05</upper>
      <!--effort>0</effort>
      <velocity>0</velocity-->
      </limit>
      <xyz>0 1 0</xyz>
      <use_parent_model_frame>1</use_parent_model_frame>
    </axis>
    </joint>
    
    
    <joint name="dedo2J" type="prismatic">
    <pose frame="">0 0 -0.1 0 0 0</pose>
    <parent>mano</parent>
    <child>dedo1</child>
    <axis>
      <dynamics>
      <damping>1</damping>
      <friction>0</friction>
      <spring_reference>0</spring_reference>
      <spring_stiffness>0</spring_stiffness>
      </dynamics> 
      <limit>
      <lower>-0.05</lower>
      <upper>0</upper>
      <!--effort>0</effort>
      <velocity>0</velocity-->
      </limit>
      <xyz>0 1 0</xyz>
      <use_parent_model_frame>1</use_parent_model_frame>
    </axis>
    </joint>
    
<plugin name="actuador" filename="libmirobot"></plugin>
    
    </model>
  </world>
</sdf>
